<?xml version="1.0" ?>
<!-- =================================================================================== -->
<!-- |    This document was autogenerated by xacro from urdf/pexod.xacro               | -->
<!-- |    EDITING THIS FILE BY HAND IS NOT RECOMMENDED                                 | -->
<!-- =================================================================================== -->
<robot name="pexod" xmlns:xacro="http://www.ros.org/wiki/xacro">
  <!-- <xacro:include filename="$(find pexod_description)/urdf/pexod_control.xacro" /> -->
  <!-- MATERIALS -->
  <material name="Color1">
    <color rgba="0.25098039215686274 0.2235294117647059 0.30980392156862746 1"/>
  </material>
  <material name="Color2">
    <color rgba="0.3686274509803922 0.32941176470588235 0.4549019607843137 1"/>
  </material>
  <material name="Color3">
    <color rgba="0.49019607843137253 0.4392156862745098 0.596078431372549 1"/>
  </material>
  <material name="Color4">
    <color rgba="0.6235294117647059 0.5843137254901961 0.7019607843137254 1"/>
  </material>
  <material name="Red">
    <color rgba="1 0 0 0.2"/>
  </material>
  <!-- END OF MATERIALS -->
  <!-- XACRO MACROS FOR VISUALS AND COLLISIONS -->
  <!-- END OF XACRO MACROS -->
  <!-- TORSO -->
  <link name="base_link">
    <visual>
      <origin rpy="0 0 0" xyz="0 0 0"/>
      <geometry>
        <cylinder length="{z_body}" radius="{r_body}"/>
      </geometry>
      <material name="Color1"/>
    </visual>
    <collision>
      <origin rpy="0 0 0" xyz="0 0 0"/>
      <geometry>
        <cylinder length="{z_body}" radius="{r_body}"/>
      </geometry>
    </collision>
    <inertial>
      <!-- CENTER OF MASS -->
      <origin rpy="0 0 0" xyz="0 0 0"/>
      <mass value="{m_body}"/>
      <!-- box inertia: 1/12*m(y^2+z^2), ... -->
      <inertia ixx="0.00357413333333" ixy="0" ixz="0" iyy="0.00508626666667" iyz="0" izz="0.00838546666667"/>
    </inertial>
  </link>
  <!-- XACRO MACRO FOR LEGS LINKS/JOINTS -->
  <!-- END OF LEG LINKS/JOINTS -->
  <joint name="body_leg_2" type="revolute">
    <parent link="base_link"/>
    <child link="leg_2_1"/>
    <limit effort="{torque_servo_1}" lower="{lower_servo_1}" upper="{upper_servo_1}" velocity="{v_servo_1}"/>
    <origin rpy="0 0 {phi_body_leg_2}" xyz="{x_body_leg_2} {y_body_leg_2} {z_body_leg_2}"/>
    <axis xyz="0 0 1"/>
    <dynamics damping="0.0"/>
  </joint>
  <link name="leg_2_1">
    <visual>
      <origin rpy="1.57079632679 0 0" xyz="0 eval[{l1}/2.] 0"/>
      <geometry>
        <cylinder length="{l1}" radius="{r1}"/>
      </geometry>
      <material name="Color2"/>
    </visual>
    <collision>
      <origin rpy="1.57079632679 0 0" xyz="0 eval[{l1}/2.] 0"/>
      <geometry>
        <box size="eval[2*{r1}] eval[2*{r1}] {l1}"/>
      </geometry>
    </collision>
    <inertial>
      <!-- CENTER OF MASS -->
      <origin rpy="1.57079632679 0 0" xyz="0 eval[{l1}/2.] 0"/>
      <mass value="{m1}"/>
      <!-- box inertia: 1/12*m(y^2+z^2), ... -->
      <inertia ixx="eval[({m1}/12.)*({r1}*{r1}+{l1}*{l1})]" ixy="0" ixz="0" iyy="eval[({m1}/12.)*({r1}*{r1}+{l1}*{l1})]" iyz="0" izz="eval[({m1}/12.)*(2*{r1}*{r1})]"/>
    </inertial>
  </link>
  <joint name="leg_2_1_2" type="revolute">
    <parent link="leg_2_1"/>
    <child link="leg_2_2"/>
    <limit effort="{torque_servo_2}" lower="{lower_servo_2}" upper="{upper_servo_2}" velocity="{v_servo_2}"/>
    <origin rpy="0 0 0" xyz="0 {l1} 0"/>
    <axis xyz="-1 0 0"/>
    <dynamics damping="0.0"/>
  </joint>
  <link name="leg_2_2">
    <visual>
      	<origin rpy="1.57079632679 0 0" xyz="0 eval[{l2}/2.] 0"/>
      <geometry>
        <cylinder length="{l2}" radius="{r2}"/>
      </geometry>
      <material name="Color3"/>
    </visual>
    <collision>
      	<origin rpy="1.57079632679 0 0" xyz="0 eval[{l2}/2.] 0"/>
      <geometry>
        <box size="eval[2*{r2}] eval[2*{r2}] {l2}"/>
      </geometry>
    </collision>
    <inertial>
      <!-- CENTER OF MASS -->
      	<origin rpy="1.57079632679 0 0" xyz="0 eval[{l2}/2.] 0"/>
      <mass value="{m2}"/>
      <!-- box inertia: 1/12*m(y^2+z^2), ... -->
      <inertia ixx="eval[({m2}/12.)*({r2}*{r2}+{l2}*{l2})]" ixy="0" ixz="0" iyy="eval[({m2}/12.)*({r2}*{r2}+{l2}*{l2})]" iyz="0" izz="eval[({m2}/12.)*(2*{r2}*{r2})]"/>
    </inertial>
  </link>
  <joint name="leg_2_2_3" type="revolute">
    <parent link="leg_2_2"/>
    <child link="leg_2_3"/>
    <limit effort="{torque_servo_3}" lower="{lower_servo_3}" upper="{upper_servo_3}" velocity="{v_servo_3}"/>
    <origin rpy="0 0 0" xyz="0 {l2} 0"/>
    <axis xyz="-1 0 0"/>
    <dynamics damping="0.0"/>
  </joint>
  <link name="leg_2_3">
    <visual>
      <origin rpy="1.57079632679 0 0" xyz="0 eval[{l3}/2.-{r3}/2.] 0"/>
      <geometry>
        <cylinder length="eval[{l3}-{r3}]" radius="{r3}"/>
      </geometry>
      <material name="Color4"/>
    </visual>
    <visual>
      <origin rpy="1.57079632679 0 0" xyz="0 eval[{l3}-{r3}] 0"/>
      <geometry>
        <sphere radius="{r3}"/>
      </geometry>
      <material name="Color4"/>
    </visual>
    <collision>
      <origin rpy="1.57079632679 0 0" xyz="0 eval[{l3}/2.-{r3}/2.] 0"/>
      <geometry>
        <box size="eval[2*{r3}] eval[2*{r3}] eval[{l3}-{r3}]"/>
      </geometry>
    </collision>
    <collision>
      <origin rpy="1.57079632679 0 0" xyz="0 eval[{l3}-{r3}] 0"/>
      <geometry>
        <sphere radius="{r3}"/>
      </geometry>
      <material name="Color4"/>
    </collision>
    <inertial>
      <!-- CENTER OF MASS -->
      <origin rpy="1.57079632679 0 0" xyz="eval[{r3}/2.] eval[{l3}/2.] 0"/>
      <mass value="{m3}"/>
      <!-- box inertia: 1/12*m(y^2+z^2), ... -->
      <inertia ixx="eval[({m3}/12.)*({r3}*{r3}+{l3}*{l3})]" ixy="0" ixz="0" iyy="eval[({m3}/12.)*({r3}*{r3}+{l3}*{l3})]" iyz="0" izz="eval[({m3}/12.)*(2*{r3}*{r3})]"/>
    </inertial>
  </link>
  <joint name="body_leg_3" type="revolute">
    <parent link="base_link"/>
    <child link="leg_3_1"/>
    <limit effort="{torque_servo_1}" lower="{lower_servo_1}" upper="{upper_servo_1}" velocity="{v_servo_1}"/>
    <origin rpy="0 0 {phi_body_leg_3}" xyz="{x_body_leg_3} {y_body_leg_3} {z_body_leg_3}"/>
    <axis xyz="0 0 1"/>
    <dynamics damping="0.0"/>
  </joint>
  <link name="leg_3_1">
    <visual>
      <origin rpy="1.57079632679 0 0" xyz="0 eval[-{l1}/2.] 0"/>
      <geometry>
        <cylinder length="{l1}" radius="{r1}"/>
      </geometry>
      <material name="Color2"/>
    </visual>
    <collision>
      <origin rpy="1.57079632679 0 0" xyz="0 eval[-{l1}/2.] 0"/>
      <geometry>
        <box size="eval[2*{r1}] eval[2*{r1}] {l1}"/>
      </geometry>
    </collision>
    <inertial>
      <!-- CENTER OF MASS -->
      <origin rpy="1.57079632679 0 0" xyz="0 eval[-{l1}/2.] 0"/>
      <mass value="{m1}"/>
      <!-- box inertia: 1/12*m(y^2+z^2), ... -->
      <inertia ixx="eval[({m1}/12.)*({r1}*{r1}+{l1}*{l1})]" ixy="0" ixz="0" iyy="eval[({m1}/12.)*({r1}*{r1}+{l1}*{l1})]" iyz="0" izz="eval[({m1}/12.)*(2*{r1}*{r1})]"/>
    </inertial>
  </link>
  <joint name="leg_3_1_2" type="revolute">
    <parent link="leg_3_1"/>
    <child link="leg_3_2"/>
    <limit effort="{torque_servo_2}" lower="{lower_servo_2}" upper="{upper_servo_2}" velocity="{v_servo_2}"/>
    <origin rpy="0 0 0" xyz="0 -{l1} 0"/>
    <axis xyz="1 0 0"/>
    <dynamics damping="0.0"/>
  </joint>
  <link name="leg_3_2">
    <visual>
      	<origin rpy="1.57079632679 0 0" xyz="0 eval[-{l2}/2.] 0"/>
      <geometry>
        <cylinder length="{l2}" radius="{r2}"/>
      </geometry>
      <material name="Color3"/>
    </visual>
    <collision>
      	<origin rpy="1.57079632679 0 0" xyz="0 eval[-{l2}/2.] 0"/>
      <geometry>
        <box size="eval[2*{r2}] eval[2*{r2}] {l2}"/>
      </geometry>
    </collision>
    <inertial>
      <!-- CENTER OF MASS -->
      	<origin rpy="1.57079632679 0 0" xyz="0 eval[-{l2}/2.] 0"/>
      <mass value="{m2}"/>
      <!-- box inertia: 1/12*m(y^2+z^2), ... -->
      <inertia ixx="eval[({m2}/12.)*({r2}*{r2}+{l2}*{l2})]" ixy="0" ixz="0" iyy="eval[({m2}/12.)*({r2}*{r2}+{l2}*{l2})]" iyz="0" izz="eval[({m2}/12.)*(2*{r2}*{r2})]"/>
    </inertial>
  </link>
  <joint name="leg_3_2_3" type="revolute">
    <parent link="leg_3_2"/>
    <child link="leg_3_3"/>
    <limit effort="{torque_servo_3}" lower="{lower_servo_3}" upper="{upper_servo_3}" velocity="{v_servo_3}"/>
    <origin rpy="0 0 0" xyz="0 -{l2} 0"/>
    <axis xyz="1 0 0"/>
    <dynamics damping="0.0"/>
  </joint>
  <link name="leg_3_3">
    <visual>
      <origin rpy="1.57079632679 0 0" xyz="0 -eval[{l3}/2.-{r3}/2.] 0"/>
      <geometry>
        <cylinder length="eval[{l3}-{r3}]" radius="{r3}"/>
      </geometry>
      <material name="Color4"/>
    </visual>
    <visual>
      <origin rpy="1.57079632679 0 0" xyz="0 -eval[{l3}-{r3}] 0"/>
      <geometry>
        <sphere radius="{r3}"/>
      </geometry>
      <material name="Color4"/>
    </visual>
    <collision>
      <origin rpy="1.57079632679 0 0" xyz="0 -eval[{l3}/2.-{r3}/2.] 0"/>
      <geometry>
        <box size="eval[2*{r3}] eval[2*{r3}] eval[{l3}-{r3}]"/>
      </geometry>
    </collision>
    <collision>
      <origin rpy="1.57079632679 0 0" xyz="0 -eval[{l3}-{r3}] 0"/>
      <geometry>
        <sphere radius="{r3}"/>
      </geometry>
      <material name="Color4"/>
    </collision>
    <inertial>
      <!-- CENTER OF MASS -->
      <origin rpy="1.57079632679 0 0" xyz="eval[{r3}/2.] eval[-{l3}/2.] 0"/>
      <mass value="{m3}"/>
      <!-- box inertia: 1/12*m(y^2+z^2), ... -->
      <inertia ixx="eval[({m3}/12.)*({r3}*{r3}+{l3}*{l3})]" ixy="0" ixz="0" iyy="eval[({m3}/12.)*({r3}*{r3}+{l3}*{l3})]" iyz="0" izz="eval[({m3}/12.)*(2*{r3}*{r3})]"/>
    </inertial>
  </link>
  <joint name="body_leg_0" type="revolute">
    <parent link="base_link"/>
    <child link="leg_0_1"/>
    <limit effort="{torque_servo_1}" lower="{lower_servo_1}" upper="{upper_servo_1}" velocity="{v_servo_1}"/>
    <origin rpy="0 0 {phi_body_leg_0}" xyz="{x_body_leg_0} {y_body_leg_0} {z_body_leg_0}"/>
    <axis xyz="0 0 1"/>
    <dynamics damping="0.0"/>
  </joint>
  <link name="leg_0_1">
    <visual>
      <origin rpy="1.57079632679 0 0" xyz="0 eval[{l1}/2.] 0"/>
      <geometry>
        <cylinder length="{l1}" radius="{r1}"/>
      </geometry>
      <material name="Color2"/>
    </visual>
    <collision>
      <origin rpy="1.57079632679 0 0" xyz="0 eval[{l1}/2.] 0"/>
      <geometry>
        <box size="eval[2*{r1}] eval[2*{r1}] {l1}"/>
      </geometry>
    </collision>
    <inertial>
      <!-- CENTER OF MASS -->
      <origin rpy="1.57079632679 0 0" xyz="0 eval[{l1}/2.] 0"/>
      <mass value="{m1}"/>
      <!-- box inertia: 1/12*m(y^2+z^2), ... -->
      <inertia ixx="eval[({m1}/12.)*({r1}*{r1}+{l1}*{l1})]" ixy="0" ixz="0" iyy="eval[({m1}/12.)*({r1}*{r1}+{l1}*{l1})]" iyz="0" izz="eval[({m1}/12.)*(2*{r1}*{r1})]"/>
    </inertial>
  </link>
  <joint name="leg_0_1_2" type="revolute">
    <parent link="leg_0_1"/>
    <child link="leg_0_2"/>
    <limit effort="{torque_servo_2}" lower="{lower_servo_2}" upper="{upper_servo_2}" velocity="{v_servo_2}"/>
    <origin rpy="0 0 0" xyz="0 {l1} 0"/>
    <axis xyz="-1 0 0"/>
    <dynamics damping="0.0"/>
  </joint>
  <link name="leg_0_2">
    <visual>
      	<origin rpy="1.57079632679 0 0" xyz="0 eval[{l2}/2.] 0"/>
      <geometry>
        <cylinder length="{l2}" radius="{r2}"/>
      </geometry>
      <material name="Color3"/>
    </visual>
    <collision>
      	<origin rpy="1.57079632679 0 0" xyz="0 eval[{l2}/2.] 0"/>
      <geometry>
        <box size="eval[2*{r2}] eval[2*{r2}] {l2}"/>
      </geometry>
    </collision>
    <inertial>
      <!-- CENTER OF MASS -->
      	<origin rpy="1.57079632679 0 0" xyz="0 eval[{l2}/2.] 0"/>
      <mass value="{m2}"/>
      <!-- box inertia: 1/12*m(y^2+z^2), ... -->
      <inertia ixx="eval[({m2}/12.)*({r2}*{r2}+{l2}*{l2})]" ixy="0" ixz="0" iyy="eval[({m2}/12.)*({r2}*{r2}+{l2}*{l2})]" iyz="0" izz="eval[({m2}/12.)*(2*{r2}*{r2})]"/>
    </inertial>
  </link>
  <joint name="leg_0_2_3" type="revolute">
    <parent link="leg_0_2"/>
    <child link="leg_0_3"/>
    <limit effort="{torque_servo_3}" lower="{lower_servo_3}" upper="{upper_servo_3}" velocity="{v_servo_3}"/>
    <origin rpy="0 0 0" xyz="0 {l2} 0"/>
    <axis xyz="-1 0 0"/>
    <dynamics damping="0.0"/>
  </joint>
  <link name="leg_0_3">
    <visual>
      <origin rpy="1.57079632679 0 0" xyz="0 eval[{l3}/2.-{r3}/2.] 0"/>
      <geometry>
        <cylinder length="eval[{l3}-{r3}]" radius="{r3}"/>
      </geometry>
      <material name="Color4"/>
    </visual>
    <visual>
      <origin rpy="1.57079632679 0 0" xyz="0 eval[{l3}-{r3}] 0"/>
      <geometry>
        <sphere radius="{r3}"/>
      </geometry>
      <material name="Color4"/>
    </visual>
    <collision>
      <origin rpy="1.57079632679 0 0" xyz="0 eval[{l3}/2.-{r3}/2.] 0"/>
      <geometry>
        <box size="eval[2*{r3}] eval[2*{r3}] eval[{l3}-{r3}]"/>
      </geometry>
    </collision>
    <collision>
      <origin rpy="1.57079632679 0 0" xyz="0 eval[{l3}-{r3}] 0"/>
      <geometry>
        <sphere radius="{r3}"/>
      </geometry>
      <material name="Color4"/>
    </collision>
    <inertial>
      <!-- CENTER OF MASS -->
      <origin rpy="1.57079632679 0 0" xyz="eval[{r3}/2.] eval[{l3}/2.] 0"/>
      <mass value="{m3}"/>
      <!-- box inertia: 1/12*m(y^2+z^2), ... -->
      <inertia ixx="eval[({m3}/12.)*({r3}*{r3}+{l3}*{l3})]" ixy="0" ixz="0" iyy="eval[({m3}/12.)*({r3}*{r3}+{l3}*{l3})]" iyz="0" izz="eval[({m3}/12.)*(2*{r3}*{r3})]"/>
    </inertial>
  </link>
  <joint name="body_leg_5" type="revolute">
    <parent link="base_link"/>
    <child link="leg_5_1"/>
    <limit effort="{torque_servo_1}" lower="{lower_servo_1}" upper="{upper_servo_1}" velocity="{v_servo_1}"/>
    <origin rpy="0 0 {phi_body_leg_5}" xyz="{x_body_leg_5} {y_body_leg_5} {z_body_leg_5}"/>
    <axis xyz="0 0 1"/>
    <dynamics damping="0.0"/>
  </joint>
  <link name="leg_5_1">
    <visual>
      <origin rpy="1.57079632679 0 0" xyz="0 eval[-{l1}/2.] 0"/>
      <geometry>
        <cylinder length="{l1}" radius="{r1}"/>
      </geometry>
      <material name="Color2"/>
    </visual>
    <collision>
      <origin rpy="1.57079632679 0 0" xyz="0 eval[-{l1}/2.] 0"/>
      <geometry>
        <box size="eval[2*{r1}] eval[2*{r1}] {l1}"/>
      </geometry>
    </collision>
    <inertial>
      <!-- CENTER OF MASS -->
      <origin rpy="1.57079632679 0 0" xyz="0 eval[-{l1}/2.] 0"/>
      <mass value="{m1}"/>
      <!-- box inertia: 1/12*m(y^2+z^2), ... -->
      <inertia ixx="eval[({m1}/12.)*({r1}*{r1}+{l1}*{l1})]" ixy="0" ixz="0" iyy="eval[({m1}/12.)*({r1}*{r1}+{l1}*{l1})]" iyz="0" izz="eval[({m1}/12.)*(2*{r1}*{r1})]"/>
    </inertial>
  </link>
  <joint name="leg_5_1_2" type="revolute">
    <parent link="leg_5_1"/>
    <child link="leg_5_2"/>
    <limit effort="{torque_servo_2}" lower="{lower_servo_2}" upper="{upper_servo_2}" velocity="{v_servo_2}"/>
    <origin rpy="0 0 0" xyz="0 -{l1} 0"/>
    <axis xyz="1 0 0"/>
    <dynamics damping="0.0"/>
  </joint>
  <link name="leg_5_2">
    <visual>
      	<origin rpy="1.57079632679 0 0" xyz="0 eval[-{l2}/2.] 0"/>
      <geometry>
        <cylinder length="{l2}" radius="{r2}"/>
      </geometry>
      <material name="Color3"/>
    </visual>
    <collision>
      	<origin rpy="1.57079632679 0 0" xyz="0 eval[-{l2}/2.] 0"/>
      <geometry>
        <box size="eval[2*{r2}] eval[2*{r2}] {l2}"/>
      </geometry>
    </collision>
    <inertial>
      <!-- CENTER OF MASS -->
      	<origin rpy="1.57079632679 0 0" xyz="0 eval[-{l2}/2.] 0"/>
      <mass value="{m2}"/>
      <!-- box inertia: 1/12*m(y^2+z^2), ... -->
      <inertia ixx="eval[({m2}/12.)*({r2}*{r2}+{l2}*{l2})]" ixy="0" ixz="0" iyy="eval[({m2}/12.)*({r2}*{r2}+{l2}*{l2})]" iyz="0" izz="eval[({m2}/12.)*(2*{r2}*{r2})]"/>
    </inertial>
  </link>
  <joint name="leg_5_2_3" type="revolute">
    <parent link="leg_5_2"/>
    <child link="leg_5_3"/>
    <limit effort="{torque_servo_3}" lower="{lower_servo_3}" upper="{upper_servo_3}" velocity="{v_servo_3}"/>
    <origin rpy="0 0 0" xyz="0 -{l2} 0"/>
    <axis xyz="1 0 0"/>
    <dynamics damping="0.0"/>
  </joint>
  <link name="leg_5_3">
    <visual>
      <origin rpy="1.57079632679 0 0" xyz="0 -eval[{l3}/2.-{r3}/2.] 0"/>
      <geometry>
        <cylinder length="eval[{l3}-{r3}]" radius="{r3}"/>
      </geometry>
      <material name="Color4"/>
    </visual>
    <visual>
      <origin rpy="1.57079632679 0 0" xyz="0 -eval[{l3}-{r3}] 0"/>
      <geometry>
        <sphere radius="{r3}"/>
      </geometry>
      <material name="Color4"/>
    </visual>
    <collision>
      <origin rpy="1.57079632679 0 0" xyz="0 -eval[{l3}/2.-{r3}/2.] 0"/>
      <geometry>
        <box size="eval[2*{r3}] eval[2*{r3}] eval[{l3}-{r3}]"/>
      </geometry>
    </collision>
    <collision>
      <origin rpy="1.57079632679 0 0" xyz="0 -eval[{l3}-{r3}] 0"/>
      <geometry>
        <sphere radius="{r3}"/>
      </geometry>
      <material name="Color4"/>
    </collision>
    <inertial>
      <!-- CENTER OF MASS -->
      <origin rpy="1.57079632679 0 0" xyz="eval[{r3}/2.] eval[-{l3}/2.] 0"/>
      <mass value="{m3}"/>
      <!-- box inertia: 1/12*m(y^2+z^2), ... -->
      <inertia ixx="eval[({m3}/12.)*({r3}*{r3}+{l3}*{l3})]" ixy="0" ixz="0" iyy="eval[({m3}/12.)*({r3}*{r3}+{l3}*{l3})]" iyz="0" izz="eval[({m3}/12.)*(2*{r3}*{r3})]"/>
    </inertial>
  </link>
  <joint name="body_leg_1" type="revolute">
    <parent link="base_link"/>
    <child link="leg_1_1"/>
    <limit effort="{torque_servo_1}" lower="{lower_servo_1}" upper="{upper_servo_1}" velocity="{v_servo_1}"/>
    <origin rpy="0 0 {phi_body_leg_1}" xyz="{x_body_leg_1} {y_body_leg_1} {z_body_leg_1}"/>
    <axis xyz="0 0 1"/>
    <dynamics damping="0.0"/>
  </joint>
  <link name="leg_1_1">
    <visual>
      <origin rpy="1.57079632679 0 0" xyz="0 eval[{l1}/2.] 0"/>
      <geometry>
        <cylinder length="{l1}" radius="{r1}"/>
      </geometry>
      <material name="Color2"/>
    </visual>
    <collision>
      <origin rpy="1.57079632679 0 0" xyz="0 eval[{l1}/2.] 0"/>
      <geometry>
        <box size="eval[2*{r1}] eval[2*{r1}] {l1}"/>
      </geometry>
    </collision>
    <inertial>
      <!-- CENTER OF MASS -->
      <origin rpy="1.57079632679 0 0" xyz="0 eval[{l1}/2.] 0"/>
      <mass value="{m1}"/>
      <!-- box inertia: 1/12*m(y^2+z^2), ... -->
      <inertia ixx="eval[({m1}/12.)*({r1}*{r1}+{l1}*{l1})]" ixy="0" ixz="0" iyy="eval[({m1}/12.)*({r1}*{r1}+{l1}*{l1})]" iyz="0" izz="eval[({m1}/12.)*(2*{r1}*{r1})]"/>
    </inertial>
  </link>
  <joint name="leg_1_1_2" type="revolute">
    <parent link="leg_1_1"/>
    <child link="leg_1_2"/>
    <limit effort="{torque_servo_2}" lower="{lower_servo_2}" upper="{upper_servo_2}" velocity="{v_servo_2}"/>
    <origin rpy="0 0 0" xyz="0 {l1} 0"/>
    <axis xyz="-1 0 0"/>
    <dynamics damping="0.0"/>
  </joint>
  <link name="leg_1_2">
    <visual>
      	<origin rpy="1.57079632679 0 0" xyz="0 eval[{l2}/2.] 0"/>
      <geometry>
        <cylinder length="{l2}" radius="{r2}"/>
      </geometry>
      <material name="Color3"/>
    </visual>
    <collision>
      	<origin rpy="1.57079632679 0 0" xyz="0 eval[{l2}/2.] 0"/>
      <geometry>
        <box size="eval[2*{r2}] eval[2*{r2}] {l2}"/>
      </geometry>
    </collision>
    <inertial>
      <!-- CENTER OF MASS -->
      	<origin rpy="1.57079632679 0 0" xyz="0 eval[{l2}/2.] 0"/>
      <mass value="{m2}"/>
      <!-- box inertia: 1/12*m(y^2+z^2), ... -->
      <inertia ixx="eval[({m2}/12.)*({r2}*{r2}+{l2}*{l2})]" ixy="0" ixz="0" iyy="eval[({m2}/12.)*({r2}*{r2}+{l2}*{l2})]" iyz="0" izz="eval[({m2}/12.)*(2*{r2}*{r2})]"/>
    </inertial>
  </link>
  <joint name="leg_1_2_3" type="revolute">
    <parent link="leg_1_2"/>
    <child link="leg_1_3"/>
    <limit effort="{torque_servo_3}" lower="{lower_servo_3}" upper="{upper_servo_3}" velocity="{v_servo_3}"/>
    <origin rpy="0 0 0" xyz="0 {l2} 0"/>
    <axis xyz="-1 0 0"/>
    <dynamics damping="0.0"/>
  </joint>
  <link name="leg_1_3">
    <visual>
      <origin rpy="1.57079632679 0 0" xyz="0 eval[{l3}/2.-{r3}/2.] 0"/>
      <geometry>
        <cylinder length="eval[{l3}-{r3}]" radius="{r3}"/>
      </geometry>
      <material name="Color4"/>
    </visual>
    <visual>
      <origin rpy="1.57079632679 0 0" xyz="0 eval[{l3}-{r3}] 0"/>
      <geometry>
        <sphere radius="{r3}"/>
      </geometry>
      <material name="Color4"/>
    </visual>
    <collision>
      <origin rpy="1.57079632679 0 0" xyz="0 eval[{l3}/2.-{r3}/2.] 0"/>
      <geometry>
        <box size="eval[2*{r3}] eval[2*{r3}] eval[{l3}-{r3}]"/>
      </geometry>
    </collision>
    <collision>
      <origin rpy="1.57079632679 0 0" xyz="0 eval[{l3}-{r3}] 0"/>
      <geometry>
        <sphere radius="{r3}"/>
      </geometry>
      <material name="Color4"/>
    </collision>
    <inertial>
      <!-- CENTER OF MASS -->
      <origin rpy="1.57079632679 0 0" xyz="eval[{r3}/2.] eval[{l3}/2.] 0"/>
      <mass value="{m3}"/>
      <!-- box inertia: 1/12*m(y^2+z^2), ... -->
      <inertia ixx="eval[({m3}/12.)*({r3}*{r3}+{l3}*{l3})]" ixy="0" ixz="0" iyy="eval[({m3}/12.)*({r3}*{r3}+{l3}*{l3})]" iyz="0" izz="eval[({m3}/12.)*(2*{r3}*{r3})]"/>
    </inertial>
  </link>
  <joint name="body_leg_4" type="revolute">
    <parent link="base_link"/>
    <child link="leg_4_1"/>
    <limit effort="{torque_servo_1}" lower="{lower_servo_1}" upper="{upper_servo_1}" velocity="{v_servo_1}"/>
    <origin rpy="0 0 {phi_body_leg_4}" xyz="{x_body_leg_4} {y_body_leg_4} {z_body_leg_4}"/>
    <axis xyz="0 0 1"/>
    <dynamics damping="0.0"/>
  </joint>
  <link name="leg_4_1">
    <visual>
      <origin rpy="1.57079632679 0 0" xyz="0 eval[-{l1}/2.] 0"/>
      <geometry>
        <cylinder length="{l1}" radius="{r1}"/>
      </geometry>
      <material name="Color2"/>
    </visual>
    <collision>
      <origin rpy="1.57079632679 0 0" xyz="0 eval[-{l1}/2.] 0"/>
      <geometry>
        <box size="eval[2*{r1}] eval[2*{r1}] {l1}"/>
      </geometry>
    </collision>
    <inertial>
      <!-- CENTER OF MASS -->
      <origin rpy="1.57079632679 0 0" xyz="0 eval[-{l1}/2.] 0"/>
      <mass value="{m1}"/>
      <!-- box inertia: 1/12*m(y^2+z^2), ... -->
      <inertia ixx="eval[({m1}/12.)*({r1}*{r1}+{l1}*{l1})]" ixy="0" ixz="0" iyy="eval[({m1}/12.)*({r1}*{r1}+{l1}*{l1})]" iyz="0" izz="eval[({m1}/12.)*(2*{r1}*{r1})]"/>
    </inertial>
  </link>
  <joint name="leg_4_1_2" type="revolute">
    <parent link="leg_4_1"/>
    <child link="leg_4_2"/>
    <limit effort="{torque_servo_2}" lower="{lower_servo_2}" upper="{upper_servo_2}" velocity="{v_servo_2}"/>
    <origin rpy="0 0 0" xyz="0 -{l1} 0"/>
    <axis xyz="1 0 0"/>
    <dynamics damping="0.0"/>
  </joint>
  <link name="leg_4_2">
    <visual>
      	<origin rpy="1.57079632679 0 0" xyz="0 eval[-{l2}/2.] 0"/>
      <geometry>
        <cylinder length="{l2}" radius="{r2}"/>
      </geometry>
      <material name="Color3"/>
    </visual>
    <collision>
      	<origin rpy="1.57079632679 0 0" xyz="0 eval[-{l2}/2.] 0"/>
      <geometry>
        <box size="eval[2*{r2}] eval[2*{r2}] {l2}"/>
      </geometry>
    </collision>
    <inertial>
      <!-- CENTER OF MASS -->
      	<origin rpy="1.57079632679 0 0" xyz="0 eval[-{l2}/2.] 0"/>
      <mass value="{m2}"/>
      <!-- box inertia: 1/12*m(y^2+z^2), ... -->
      <inertia ixx="eval[({m2}/12.)*({r2}*{r2}+{l2}*{l2})]" ixy="0" ixz="0" iyy="eval[({m2}/12.)*({r2}*{r2}+{l2}*{l2})]" iyz="0" izz="eval[({m2}/12.)*(2*{r2}*{r2})]"/>
    </inertial>
  </link>
  <joint name="leg_4_2_3" type="revolute">
    <parent link="leg_4_2"/>
    <child link="leg_4_3"/>
    <limit effort="{torque_servo_3}" lower="{lower_servo_3}" upper="{upper_servo_3}" velocity="{v_servo_3}"/>
    <origin rpy="0 0 0" xyz="0 -{l2} 0"/>
    <axis xyz="1 0 0"/>
    <dynamics damping="0.0"/>
  </joint>
  <link name="leg_4_3">
    <visual>
      <origin rpy="1.57079632679 0 0" xyz="0 -eval[{l3}/2.-{r3}/2.] 0"/>
      <geometry>
        <cylinder length="eval[{l3}-{r3}]" radius="{r3}"/>
      </geometry>
      <material name="Color4"/>
    </visual>
    <visual>
      <origin rpy="1.57079632679 0 0" xyz="0 -eval[{l3}-{r3}] 0"/>
      <geometry>
        <sphere radius="{r3}"/>
      </geometry>
      <material name="Color4"/>
    </visual>
    <collision>
      <origin rpy="1.57079632679 0 0" xyz="0 -eval[{l3}/2.-{r3}/2.] 0"/>
      <geometry>
        <box size="eval[2*{r3}] eval[2*{r3}] eval[{l3}-{r3}]"/>
      </geometry>
    </collision>
    <collision>
      <origin rpy="1.57079632679 0 0" xyz="0 -eval[{l3}-{r3}] 0"/>
      <geometry>
        <sphere radius="{r3}"/>
      </geometry>
      <material name="Color4"/>
    </collision>
    <inertial>
      <!-- CENTER OF MASS -->
      <origin rpy="1.57079632679 0 0" xyz="eval[{r3}/2.] eval[-{l3}/2.] 0"/>
      <mass value="{m3}"/>
      <!-- box inertia: 1/12*m(y^2+z^2), ... -->
      <inertia ixx="eval[({m3}/12.)*({r3}*{r3}+{l3}*{l3})]" ixy="0" ixz="0" iyy="eval[({m3}/12.)*({r3}*{r3}+{l3}*{l3})]" iyz="0" izz="eval[({m3}/12.)*(2*{r3}*{r3})]"/>
    </inertial>
  </link>
  <!-- END OF LEG LINKS/JOINTS -->
</robot>

