<?xml version="1.0" ?>
<!-- =================================================================================== -->
<!-- |    This document was autogenerated by xacro from urdf/pexod.xacro               | -->
<!-- |    EDITING THIS FILE BY HAND IS NOT RECOMMENDED                                 | -->
<!-- =================================================================================== -->
<robot name="pexod" xmlns:xacro="http://www.ros.org/wiki/xacro">
  <!-- <xacro:include filename="$(find pexod_description)/urdf/pexod_control.xacro" /> -->
  <!-- MATERIALS -->
  <material name="Blue">
    <color rgba="0 0 1 1"/>
  </material>
  <material name="Red">
    <color rgba="1 0 0 1"/>
  </material>
  <material name="Green">
    <color rgba="0 1 0 1"/>
  </material>
  <material name="Yellow">
    <color rgba="1 1 0 1"/>
  </material>
  <material name="LightGrey">
    <color rgba="0.6 0.6 0.6 1.0"/>
  </material>
  <!-- END OF MATERIALS -->
  <!-- XACRO MACROS FOR VISUALS AND COLLISIONS -->
  <!-- END OF XACRO MACROS -->
  <!-- TORSO -->
  <link name="base_link">
    <visual>
      <origin rpy="0 0 0" xyz="0 0 0"/>
      <geometry>
        <box size="0.24 0.2 0.04"/>
      </geometry>
      <material name="Blue"/>
    </visual>
    <collision>
      <origin rpy="0 0 0" xyz="0 0 0"/>
      <geometry>
        <box size="0.24 0.2 0.04"/>
      </geometry>
    </collision>
    <inertial>
      <!-- CENTER OF MASS -->
      <origin rpy="0 0 0" xyz="0 0 0"/>
      <mass value="mbody"/>
      <!-- box inertia: 1/12*m(y^2+z^2), ... -->
      <inertia ixx="0.00357413333333" ixy="0" ixz="0" iyy="0.00508626666667" iyz="0" izz="0.00838546666667"/>
    </inertial>
  </link>
  <!-- XACRO MACRO FOR LEGS LINKS/JOINTS -->
  <!-- END OF LEG LINKS/JOINTS -->
  <joint name="body_leg_2" type="revolute">
    <parent link="base_link"/>
    <child link="leg_2_1"/>
    <limit effort="torque_servo_1" lower="lower_servo_1" upper="upper_servo_1" velocity="v_servo_1"/>
    <origin rpy="0 0 phi_body_leg_2" xyz="x_body_leg_2 y_body_leg_2 z_body_leg_2"/>
    <!-- <xacro:if value="${index == 5 or index == 4 or index == 3}">
                <axis xyz="0 0 1"/>
            </xacro:if>
            <xacro:if value="${index == 2 or index == 1 or index == 0}"> -->
    <axis xyz="0 0 1"/>
    <!-- </xacro:if> -->
    <dynamics damping="0.0"/>
  </joint>
  <link name="leg_2_1">
    <visual>
      <origin rpy="1.57079632679 0 0" xyz="eval[r1/2.] eval[l1/2.] 0"/>
      <geometry>
        <cylinder length="l1" radius="r1"/>
      </geometry>
      <material name="Red"/>
    </visual>
    <collision>
      <origin rpy="1.57079632679 0 0" xyz="eval[r1/2.] eval[l1/2.] 0"/>
      <geometry>
        <box size="r1 r1 l1"/>
      </geometry>
    </collision>
    <inertial>
      <!-- CENTER OF MASS -->
      <origin rpy="1.57079632679 0 0" xyz="eval[r1/2.] eval[l1/2.] 0"/>
      <mass value="m1"/>
      <!-- box inertia: 1/12*m(y^2+z^2), ... -->
      <inertia ixx="eval[(m1/12.)*(r1*r1+l1*l1)]" ixy="0" ixz="0" iyy="eval[(m1/12.)*(r1*r1+l1*l1)]" iyz="0" izz="eval[(m1/12.)*(2*r1*r1)]"/>
    </inertial>
  </link>
  <joint name="leg_2_1_2" type="revolute">
    <parent link="leg_2_1"/>
    <child link="leg_2_2"/>
    <limit effort="torque_servo_2" lower="lower_servo_2" upper="upper_servo_2" velocity="v_servo_2"/>
    <origin rpy="0 0 0" xyz="0 l1 0"/>
    <axis xyz="1 0 0"/>
    <dynamics damping="0.0"/>
  </joint>
  <link name="leg_2_2">
    <visual>
      <origin rpy="1.57079632679 0 0" xyz="eval[r2/2.] eval[l2/2.] 0"/>
      <geometry>
        <cylinder length="l2" radius="r2"/>
      </geometry>
      <material name="Blue"/>
    </visual>
    <collision>
      <origin rpy="1.57079632679 0 0" xyz="eval[r2/2.] eval[l2/2.] 0"/>
      <geometry>
        <box size="r2 r2 l2"/>
      </geometry>
    </collision>
    <inertial>
      <!-- CENTER OF MASS -->
      <origin rpy="1.57079632679 0 0" xyz="eval[r2/2.] eval[l2/2.] 0"/>
      <mass value="m2"/>
      <!-- box inertia: 1/12*m(y^2+z^2), ... -->
      <inertia ixx="eval[(m2/12.)*(r2*r2+l2*l2)]" ixy="0" ixz="0" iyy="eval[(m2/12.)*(r2*r2+l2*l2)]" iyz="0" izz="eval[(m2/12.)*(2*r2*r2)]"/>
    </inertial>
  </link>
  <joint name="leg_2_2_3" type="revolute">
    <parent link="leg_2_2"/>
    <child link="leg_2_3"/>
    <limit effort="torque_servo_3" lower="lower_servo_3" upper="upper_servo_3" velocity="v_servo_3"/>
    <origin rpy="-1.57079632679 0 0" xyz="0 l2 0"/>
    <axis xyz="-1 0 0"/>
    <dynamics damping="0.0"/>
  </joint>
  <link name="leg_2_3">
    <visual>
      <origin rpy="1.57079632679 0 0" xyz="eval[r3/2.] eval[l3/2.] 0"/>
      <geometry>
        <cylinder length="l3" radius="r3"/>
      </geometry>
      <material name="Red"/>
    </visual>
    <visual>
      <origin rpy="1.57079632679 0 0" xyz="eval[r3/2.] eval[l3-r3/2.] 0"/>
      <geometry>
        <sphere radius="r3"/>
      </geometry>
      <material name="Red"/>
    </visual>
    <collision>
      <origin rpy="1.57079632679 0 0" xyz="eval[r3/2.] eval[l3/2.] 0"/>
      <geometry>
        <box size="r3 r3 l3"/>
      </geometry>
    </collision>
    <collision>
      <origin rpy="1.57079632679 0 0" xyz="eval[r3/2.] eval[l3-r3/2.] 0"/>
      <geometry>
        <sphere radius="r3"/>
      </geometry>
      <material name="Red"/>
    </collision>
    <inertial>
      <!-- CENTER OF MASS -->
      <origin rpy="1.57079632679 0 0" xyz="eval[r3/2.] eval[l3/2.] 0"/>
      <mass value="m3"/>
      <!-- box inertia: 1/12*m(y^2+z^2), ... -->
      <inertia ixx="eval[(m3/12.)*(r3*r3+l3*l3)]" ixy="0" ixz="0" iyy="eval[(m3/12.)*(r3*r3+l3*l3)]" iyz="0" izz="eval[(m3/12.)*(2*r3*r3)]"/>
    </inertial>
  </link>
  <joint name="body_leg_3" type="revolute">
    <parent link="base_link"/>
    <child link="leg_3_1"/>
    <limit effort="torque_servo_1" lower="lower_servo_1" upper="upper_servo_1" velocity="v_servo_1"/>
    <origin rpy="0 0 phi_body_leg_3" xyz="x_body_leg_3 y_body_leg_3 z_body_leg_3"/>
    <!-- <xacro:if value="${index == 5 or index == 4 or index == 3}">
                <axis xyz="0 0 1"/>
            </xacro:if>
            <xacro:if value="${index == 2 or index == 1 or index == 0}"> -->
    <axis xyz="0 0 1"/>
    <!-- </xacro:if> -->
    <dynamics damping="0.0"/>
  </joint>
  <link name="leg_3_1">
    <visual>
      <origin rpy="1.57079632679 0 0" xyz="eval[r1/2.] eval[-l1/2.] 0"/>
      <geometry>
        <cylinder length="l1" radius="r1"/>
      </geometry>
      <material name="Red"/>
    </visual>
    <collision>
      <origin rpy="1.57079632679 0 0" xyz="eval[r1/2.] eval[-l1/2.] 0"/>
      <geometry>
        <box size="r1 r1 l1"/>
      </geometry>
    </collision>
    <inertial>
      <!-- CENTER OF MASS -->
      <origin rpy="1.57079632679 0 0" xyz="eval[r1/2.] eval[-l1/2.] 0"/>
      <mass value="m1"/>
      <!-- box inertia: 1/12*m(y^2+z^2), ... -->
      <inertia ixx="eval[(m1/12.)*(r1*r1+l1*l1)]" ixy="0" ixz="0" iyy="eval[(m1/12.)*(r1*r1+l1*l1)]" iyz="0" izz="eval[(m1/12.)*(2*r1*r1)]"/>
    </inertial>
  </link>
  <joint name="leg_3_1_2" type="revolute">
    <parent link="leg_3_1"/>
    <child link="leg_3_2"/>
    <limit effort="torque_servo_2" lower="lower_servo_2" upper="upper_servo_2" velocity="v_servo_2"/>
    <origin rpy="0 0 0" xyz="0 -l1 0"/>
    <axis xyz="-1 0 0"/>
    <dynamics damping="0.0"/>
  </joint>
  <link name="leg_3_2">
    <visual>
      <origin rpy="1.57079632679 0 0" xyz="eval[r2/2.] eval[-l2/2.] 0"/>
      <geometry>
        <cylinder length="l2" radius="r2"/>
      </geometry>
      <material name="Blue"/>
    </visual>
    <collision>
      <origin rpy="1.57079632679 0 0" xyz="eval[r2/2.] eval[-l2/2.] 0"/>
      <geometry>
        <box size="r2 r2 l2"/>
      </geometry>
    </collision>
    <inertial>
      <!-- CENTER OF MASS -->
      <origin rpy="1.57079632679 0 0" xyz="eval[r2/2.] eval[-l2/2.] 0"/>
      <mass value="m2"/>
      <!-- box inertia: 1/12*m(y^2+z^2), ... -->
      <inertia ixx="eval[(m2/12.)*(r2*r2+l2*l2)]" ixy="0" ixz="0" iyy="eval[(m2/12.)*(r2*r2+l2*l2)]" iyz="0" izz="eval[(m2/12.)*(2*r2*r2)]"/>
    </inertial>
  </link>
  <joint name="leg_3_2_3" type="revolute">
    <parent link="leg_3_2"/>
    <child link="leg_3_3"/>
    <limit effort="torque_servo_3" lower="lower_servo_3" upper="upper_servo_3" velocity="v_servo_3"/>
    <origin rpy="1.57079632679 0 0" xyz="0 -l2 0"/>
    <axis xyz="1 0 0"/>
    <dynamics damping="0.0"/>
  </joint>
  <link name="leg_3_3">
    <visual>
      <origin rpy="1.57079632679 0 0" xyz="eval[r3/2.] eval[-l3/2.] 0"/>
      <geometry>
        <cylinder length="l3" radius="r3"/>
      </geometry>
      <material name="Red"/>
    </visual>
    <visual>
      <origin rpy="1.57079632679 0 0" xyz="0.0125 -0.1275 0"/>
      <geometry>
        <sphere radius="r3"/>
      </geometry>
      <material name="Red"/>
    </visual>
    <collision>
      <origin rpy="1.57079632679 0 0" xyz="eval[r3/2.] eval[-l3/2.] 0"/>
      <geometry>
        <box size="r3 r3 l3"/>
      </geometry>
    </collision>
    <collision>
      <origin rpy="1.57079632679 0 0" xyz="0.0125 -0.1275 0"/>
      <geometry>
        <sphere radius="r3"/>
      </geometry>
      <material name="Red"/>
    </collision>
    <inertial>
      <!-- CENTER OF MASS -->
      <origin rpy="1.57079632679 0 0" xyz="eval[r3/2.] eval[-l3/2.] 0"/>
      <mass value="m3"/>
      <!-- box inertia: 1/12*m(y^2+z^2), ... -->
      <inertia ixx="eval[(m3/12.)*(r3*r3+l3*l3)]" ixy="0" ixz="0" iyy="eval[(m3/12.)*(r3*r3+l3*l3)]" iyz="0" izz="eval[(m3/12.)*(2*r3*r3)]"/>
    </inertial>
  </link>
  <joint name="body_leg_0" type="revolute">
    <parent link="base_link"/>
    <child link="leg_0_1"/>
    <limit effort="torque_servo_1" lower="lower_servo_1" upper="upper_servo_1" velocity="v_servo_1"/>
    <origin rpy="0 0 phi_body_leg_0" xyz="x_body_leg_0 y_body_leg_0 z_body_leg_0"/>
    <!-- <xacro:if value="${index == 5 or index == 4 or index == 3}">
                <axis xyz="0 0 1"/>
            </xacro:if>
            <xacro:if value="${index == 2 or index == 1 or index == 0}"> -->
    <axis xyz="0 0 1"/>
    <!-- </xacro:if> -->
    <dynamics damping="0.0"/>
  </joint>
  <link name="leg_0_1">
    <visual>
      <origin rpy="1.57079632679 0 0" xyz="eval[r1/2.] eval[l1/2.] 0"/>
      <geometry>
        <cylinder length="l1" radius="r1"/>
      </geometry>
      <material name="Red"/>
    </visual>
    <collision>
      <origin rpy="1.57079632679 0 0" xyz="eval[r1/2.] eval[l1/2.] 0"/>
      <geometry>
        <box size="r1 r1 l1"/>
      </geometry>
    </collision>
    <inertial>
      <!-- CENTER OF MASS -->
      <origin rpy="1.57079632679 0 0" xyz="eval[r1/2.] eval[l1/2.] 0"/>
      <mass value="m1"/>
      <!-- box inertia: 1/12*m(y^2+z^2), ... -->
      <inertia ixx="eval[(m1/12.)*(r1*r1+l1*l1)]" ixy="0" ixz="0" iyy="eval[(m1/12.)*(r1*r1+l1*l1)]" iyz="0" izz="eval[(m1/12.)*(2*r1*r1)]"/>
    </inertial>
  </link>
  <joint name="leg_0_1_2" type="revolute">
    <parent link="leg_0_1"/>
    <child link="leg_0_2"/>
    <limit effort="torque_servo_2" lower="lower_servo_2" upper="upper_servo_2" velocity="v_servo_2"/>
    <origin rpy="0 0 0" xyz="0 l1 0"/>
    <axis xyz="1 0 0"/>
    <dynamics damping="0.0"/>
  </joint>
  <link name="leg_0_2">
    <visual>
      <origin rpy="1.57079632679 0 0" xyz="eval[r2/2.] eval[l2/2.] 0"/>
      <geometry>
        <cylinder length="l2" radius="r2"/>
      </geometry>
      <material name="Blue"/>
    </visual>
    <collision>
      <origin rpy="1.57079632679 0 0" xyz="eval[r2/2.] eval[l2/2.] 0"/>
      <geometry>
        <box size="r2 r2 l2"/>
      </geometry>
    </collision>
    <inertial>
      <!-- CENTER OF MASS -->
      <origin rpy="1.57079632679 0 0" xyz="eval[r2/2.] eval[l2/2.] 0"/>
      <mass value="m2"/>
      <!-- box inertia: 1/12*m(y^2+z^2), ... -->
      <inertia ixx="eval[(m2/12.)*(r2*r2+l2*l2)]" ixy="0" ixz="0" iyy="eval[(m2/12.)*(r2*r2+l2*l2)]" iyz="0" izz="eval[(m2/12.)*(2*r2*r2)]"/>
    </inertial>
  </link>
  <joint name="leg_0_2_3" type="revolute">
    <parent link="leg_0_2"/>
    <child link="leg_0_3"/>
    <limit effort="torque_servo_3" lower="lower_servo_3" upper="upper_servo_3" velocity="v_servo_3"/>
    <origin rpy="-1.57079632679 0 0" xyz="0 l2 0"/>
    <axis xyz="-1 0 0"/>
    <dynamics damping="0.0"/>
  </joint>
  <link name="leg_0_3">
    <visual>
      <origin rpy="1.57079632679 0 0" xyz="eval[r3/2.] eval[l3/2.] 0"/>
      <geometry>
        <cylinder length="l3" radius="r3"/>
      </geometry>
      <material name="Red"/>
    </visual>
    <visual>
      <origin rpy="1.57079632679 0 0" xyz="eval[r3/2.] eval[l3-r3/2.] 0"/>
      <geometry>
        <sphere radius="r3"/>
      </geometry>
      <material name="Red"/>
    </visual>
    <collision>
      <origin rpy="1.57079632679 0 0" xyz="eval[r3/2.] eval[l3/2.] 0"/>
      <geometry>
        <box size="r3 r3 l3"/>
      </geometry>
    </collision>
    <collision>
      <origin rpy="1.57079632679 0 0" xyz="eval[r3/2.] eval[l3-r3/2.] 0"/>
      <geometry>
        <sphere radius="r3"/>
      </geometry>
      <material name="Red"/>
    </collision>
    <inertial>
      <!-- CENTER OF MASS -->
      <origin rpy="1.57079632679 0 0" xyz="eval[r3/2.] eval[l3/2.] 0"/>
      <mass value="m3"/>
      <!-- box inertia: 1/12*m(y^2+z^2), ... -->
      <inertia ixx="eval[(m3/12.)*(r3*r3+l3*l3)]" ixy="0" ixz="0" iyy="eval[(m3/12.)*(r3*r3+l3*l3)]" iyz="0" izz="eval[(m3/12.)*(2*r3*r3)]"/>
    </inertial>
  </link>
  <joint name="body_leg_5" type="revolute">
    <parent link="base_link"/>
    <child link="leg_5_1"/>
    <limit effort="torque_servo_1" lower="lower_servo_1" upper="upper_servo_1" velocity="v_servo_1"/>
    <origin rpy="0 0 phi_body_leg_5" xyz="x_body_leg_5 y_body_leg_5 z_body_leg_5"/>
    <!-- <xacro:if value="${index == 5 or index == 4 or index == 3}">
                <axis xyz="0 0 1"/>
            </xacro:if>
            <xacro:if value="${index == 2 or index == 1 or index == 0}"> -->
    <axis xyz="0 0 1"/>
    <!-- </xacro:if> -->
    <dynamics damping="0.0"/>
  </joint>
  <link name="leg_5_1">
    <visual>
      <origin rpy="1.57079632679 0 0" xyz="eval[r1/2.] eval[-l1/2.] 0"/>
      <geometry>
        <cylinder length="l1" radius="r1"/>
      </geometry>
      <material name="Red"/>
    </visual>
    <collision>
      <origin rpy="1.57079632679 0 0" xyz="eval[r1/2.] eval[-l1/2.] 0"/>
      <geometry>
        <box size="r1 r1 l1"/>
      </geometry>
    </collision>
    <inertial>
      <!-- CENTER OF MASS -->
      <origin rpy="1.57079632679 0 0" xyz="eval[r1/2.] eval[-l1/2.] 0"/>
      <mass value="m1"/>
      <!-- box inertia: 1/12*m(y^2+z^2), ... -->
      <inertia ixx="eval[(m1/12.)*(r1*r1+l1*l1)]" ixy="0" ixz="0" iyy="eval[(m1/12.)*(r1*r1+l1*l1)]" iyz="0" izz="eval[(m1/12.)*(2*r1*r1)]"/>
    </inertial>
  </link>
  <joint name="leg_5_1_2" type="revolute">
    <parent link="leg_5_1"/>
    <child link="leg_5_2"/>
    <limit effort="torque_servo_2" lower="lower_servo_2" upper="upper_servo_2" velocity="v_servo_2"/>
    <origin rpy="0 0 0" xyz="0 -l1 0"/>
    <axis xyz="-1 0 0"/>
    <dynamics damping="0.0"/>
  </joint>
  <link name="leg_5_2">
    <visual>
      <origin rpy="1.57079632679 0 0" xyz="eval[r2/2.] eval[-l2/2.] 0"/>
      <geometry>
        <cylinder length="l2" radius="r2"/>
      </geometry>
      <material name="Blue"/>
    </visual>
    <collision>
      <origin rpy="1.57079632679 0 0" xyz="eval[r2/2.] eval[-l2/2.] 0"/>
      <geometry>
        <box size="r2 r2 l2"/>
      </geometry>
    </collision>
    <inertial>
      <!-- CENTER OF MASS -->
      <origin rpy="1.57079632679 0 0" xyz="eval[r2/2.] eval[-l2/2.] 0"/>
      <mass value="m2"/>
      <!-- box inertia: 1/12*m(y^2+z^2), ... -->
      <inertia ixx="eval[(m2/12.)*(r2*r2+l2*l2)]" ixy="0" ixz="0" iyy="eval[(m2/12.)*(r2*r2+l2*l2)]" iyz="0" izz="eval[(m2/12.)*(2*r2*r2)]"/>
    </inertial>
  </link>
  <joint name="leg_5_2_3" type="revolute">
    <parent link="leg_5_2"/>
    <child link="leg_5_3"/>
    <limit effort="torque_servo_3" lower="lower_servo_3" upper="upper_servo_3" velocity="v_servo_3"/>
    <origin rpy="1.57079632679 0 0" xyz="0 -l2 0"/>
    <axis xyz="1 0 0"/>
    <dynamics damping="0.0"/>
  </joint>
  <link name="leg_5_3">
    <visual>
      <origin rpy="1.57079632679 0 0" xyz="eval[r3/2.] eval[-l3/2.] 0"/>
      <geometry>
        <cylinder length="l3" radius="r3"/>
      </geometry>
      <material name="Red"/>
    </visual>
    <visual>
      <origin rpy="1.57079632679 0 0" xyz="0.0125 -0.1275 0"/>
      <geometry>
        <sphere radius="r3"/>
      </geometry>
      <material name="Red"/>
    </visual>
    <collision>
      <origin rpy="1.57079632679 0 0" xyz="eval[r3/2.] eval[-l3/2.] 0"/>
      <geometry>
        <box size="r3 r3 l3"/>
      </geometry>
    </collision>
    <collision>
      <origin rpy="1.57079632679 0 0" xyz="0.0125 -0.1275 0"/>
      <geometry>
        <sphere radius="r3"/>
      </geometry>
      <material name="Red"/>
    </collision>
    <inertial>
      <!-- CENTER OF MASS -->
      <origin rpy="1.57079632679 0 0" xyz="eval[r3/2.] eval[-l3/2.] 0"/>
      <mass value="m3"/>
      <!-- box inertia: 1/12*m(y^2+z^2), ... -->
      <inertia ixx="eval[(m3/12.)*(r3*r3+l3*l3)]" ixy="0" ixz="0" iyy="eval[(m3/12.)*(r3*r3+l3*l3)]" iyz="0" izz="eval[(m3/12.)*(2*r3*r3)]"/>
    </inertial>
  </link>
  <joint name="body_leg_1" type="revolute">
    <parent link="base_link"/>
    <child link="leg_1_1"/>
    <limit effort="torque_servo_1" lower="lower_servo_1" upper="upper_servo_1" velocity="v_servo_1"/>
    <origin rpy="0 0 phi_body_leg_1" xyz="x_body_leg_1 y_body_leg_1 z_body_leg_1"/>
    <!-- <xacro:if value="${index == 5 or index == 4 or index == 3}">
                <axis xyz="0 0 1"/>
            </xacro:if>
            <xacro:if value="${index == 2 or index == 1 or index == 0}"> -->
    <axis xyz="0 0 1"/>
    <!-- </xacro:if> -->
    <dynamics damping="0.0"/>
  </joint>
  <link name="leg_1_1">
    <visual>
      <origin rpy="1.57079632679 0 0" xyz="eval[r1/2.] eval[l1/2.] 0"/>
      <geometry>
        <cylinder length="l1" radius="r1"/>
      </geometry>
      <material name="Red"/>
    </visual>
    <collision>
      <origin rpy="1.57079632679 0 0" xyz="eval[r1/2.] eval[l1/2.] 0"/>
      <geometry>
        <box size="r1 r1 l1"/>
      </geometry>
    </collision>
    <inertial>
      <!-- CENTER OF MASS -->
      <origin rpy="1.57079632679 0 0" xyz="eval[r1/2.] eval[l1/2.] 0"/>
      <mass value="m1"/>
      <!-- box inertia: 1/12*m(y^2+z^2), ... -->
      <inertia ixx="eval[(m1/12.)*(r1*r1+l1*l1)]" ixy="0" ixz="0" iyy="eval[(m1/12.)*(r1*r1+l1*l1)]" iyz="0" izz="eval[(m1/12.)*(2*r1*r1)]"/>
    </inertial>
  </link>
  <joint name="leg_1_1_2" type="revolute">
    <parent link="leg_1_1"/>
    <child link="leg_1_2"/>
    <limit effort="torque_servo_2" lower="lower_servo_2" upper="upper_servo_2" velocity="v_servo_2"/>
    <origin rpy="0 0 0" xyz="0 l1 0"/>
    <axis xyz="1 0 0"/>
    <dynamics damping="0.0"/>
  </joint>
  <link name="leg_1_2">
    <visual>
      <origin rpy="1.57079632679 0 0" xyz="eval[r2/2.] eval[l2/2.] 0"/>
      <geometry>
        <cylinder length="l2" radius="r2"/>
      </geometry>
      <material name="Blue"/>
    </visual>
    <collision>
      <origin rpy="1.57079632679 0 0" xyz="eval[r2/2.] eval[l2/2.] 0"/>
      <geometry>
        <box size="r2 r2 l2"/>
      </geometry>
    </collision>
    <inertial>
      <!-- CENTER OF MASS -->
      <origin rpy="1.57079632679 0 0" xyz="eval[r2/2.] eval[l2/2.] 0"/>
      <mass value="m2"/>
      <!-- box inertia: 1/12*m(y^2+z^2), ... -->
      <inertia ixx="eval[(m2/12.)*(r2*r2+l2*l2)]" ixy="0" ixz="0" iyy="eval[(m2/12.)*(r2*r2+l2*l2)]" iyz="0" izz="eval[(m2/12.)*(2*r2*r2)]"/>
    </inertial>
  </link>
  <joint name="leg_1_2_3" type="revolute">
    <parent link="leg_1_2"/>
    <child link="leg_1_3"/>
    <limit effort="torque_servo_3" lower="lower_servo_3" upper="upper_servo_3" velocity="v_servo_3"/>
    <origin rpy="-1.57079632679 0 0" xyz="0 l2 0"/>
    <axis xyz="-1 0 0"/>
    <dynamics damping="0.0"/>
  </joint>
  <link name="leg_1_3">
    <visual>
      <origin rpy="1.57079632679 0 0" xyz="eval[r3/2.] eval[l3/2.] 0"/>
      <geometry>
        <cylinder length="l3" radius="r3"/>
      </geometry>
      <material name="Red"/>
    </visual>
    <visual>
      <origin rpy="1.57079632679 0 0" xyz="eval[r3/2.] eval[l3-r3/2.] 0"/>
      <geometry>
        <sphere radius="r3"/>
      </geometry>
      <material name="Red"/>
    </visual>
    <collision>
      <origin rpy="1.57079632679 0 0" xyz="eval[r3/2.] eval[l3/2.] 0"/>
      <geometry>
        <box size="r3 r3 l3"/>
      </geometry>
    </collision>
    <collision>
      <origin rpy="1.57079632679 0 0" xyz="eval[r3/2.] eval[l3-r3/2.] 0"/>
      <geometry>
        <sphere radius="r3"/>
      </geometry>
      <material name="Red"/>
    </collision>
    <inertial>
      <!-- CENTER OF MASS -->
      <origin rpy="1.57079632679 0 0" xyz="eval[r3/2.] eval[l3/2.] 0"/>
      <mass value="m3"/>
      <!-- box inertia: 1/12*m(y^2+z^2), ... -->
      <inertia ixx="eval[(m3/12.)*(r3*r3+l3*l3)]" ixy="0" ixz="0" iyy="eval[(m3/12.)*(r3*r3+l3*l3)]" iyz="0" izz="eval[(m3/12.)*(2*r3*r3)]"/>
    </inertial>
  </link>
  <joint name="body_leg_4" type="revolute">
    <parent link="base_link"/>
    <child link="leg_4_1"/>
    <limit effort="torque_servo_1" lower="lower_servo_1" upper="upper_servo_1" velocity="v_servo_1"/>
    <origin rpy="0 0 phi_body_leg_4" xyz="x_body_leg_4y_body_leg_4 z_body_leg_4"/>
    <!-- <xacro:if value="${index == 5 or index == 4 or index == 3}">
                <axis xyz="0 0 1"/>
            </xacro:if>
            <xacro:if value="${index == 2 or index == 1 or index == 0}"> -->
    <axis xyz="0 0 1"/>
    <!-- </xacro:if> -->
    <dynamics damping="0.0"/>
  </joint>
  <link name="leg_4_1">
    <visual>
      <origin rpy="1.57079632679 0 0" xyz="eval[r1/2.] eval[-l1/2.] 0"/>
      <geometry>
        <cylinder length="l1" radius="r1"/>
      </geometry>
      <material name="Red"/>
    </visual>
    <collision>
      <origin rpy="1.57079632679 0 0" xyz="eval[r1/2.] eval[-l1/2.] 0"/>
      <geometry>
        <box size="r1 r1 l1"/>
      </geometry>
    </collision>
    <inertial>
      <!-- CENTER OF MASS -->
      <origin rpy="1.57079632679 0 0" xyz="eval[r1/2.] eval[-l1/2.] 0"/>
      <mass value="m1"/>
      <!-- box inertia: 1/12*m(y^2+z^2), ... -->
      <inertia ixx="eval[(m1/12.)*(r1*r1+l1*l1)]" ixy="0" ixz="0" iyy="eval[(m1/12.)*(r1*r1+l1*l1)]" iyz="0" izz="eval[(m1/12.)*(2*r1*r1)]"/>
    </inertial>
  </link>
  <joint name="leg_4_1_2" type="revolute">
    <parent link="leg_4_1"/>
    <child link="leg_4_2"/>
    <limit effort="torque_servo_2" lower="lower_servo_2" upper="upper_servo_2" velocity="v_servo_2"/>
    <origin rpy="0 0 0" xyz="0 -l1 0"/>
    <axis xyz="-1 0 0"/>
    <dynamics damping="0.0"/>
  </joint>
  <link name="leg_4_2">
    <visual>
      <origin rpy="1.57079632679 0 0" xyz="eval[r2/2.] eval[-l2/2.] 0"/>
      <geometry>
        <cylinder length="l2" radius="r2"/>
      </geometry>
      <material name="Blue"/>
    </visual>
    <collision>
      <origin rpy="1.57079632679 0 0" xyz="eval[r2/2.] eval[-l2/2.] 0"/>
      <geometry>
        <box size="r2 r2 l2"/>
      </geometry>
    </collision>
    <inertial>
      <!-- CENTER OF MASS -->
      <origin rpy="1.57079632679 0 0" xyz="eval[r2/2.] eval[-l2/2.] 0"/>
      <mass value="m2"/>
      <!-- box inertia: 1/12*m(y^2+z^2), ... -->
      <inertia ixx="eval[(m2/12.)*(r2*r2+l2*l2)]" ixy="0" ixz="0" iyy="eval[(m2/12.)*(r2*r2+l2*l2)]" iyz="0" izz="eval[(m2/12.)*(2*r2*r2)]"/>
    </inertial>
  </link>
  <joint name="leg_4_2_3" type="revolute">
    <parent link="leg_4_2"/>
    <child link="leg_4_3"/>
    <limit effort="torque_servo_3" lower="lower_servo_3" upper="upper_servo_3" velocity="v_servo_3"/>
    <origin rpy="1.57079632679 0 0" xyz="0 -l2 0"/>
    <axis xyz="1 0 0"/>
    <dynamics damping="0.0"/>
  </joint>
  <link name="leg_4_3">
    <visual>
      <origin rpy="1.57079632679 0 0" xyz="eval[r3/2.] eval[-l3/2.] 0"/>
      <geometry>
        <cylinder length="l3" radius="r3"/>
      </geometry>
      <material name="Red"/>
    </visual>
    <visual>
      <origin rpy="1.57079632679 0 0" xyz="0.0125 -0.1275 0"/>
      <geometry>
        <sphere radius="r3"/>
      </geometry>
      <material name="Red"/>
    </visual>
    <collision>
      <origin rpy="1.57079632679 0 0" xyz="eval[r3/2.] eval[-l3/2.] 0"/>
      <geometry>
        <box size="r3 r3 l3"/>
      </geometry>
    </collision>
    <collision>
      <origin rpy="1.57079632679 0 0" xyz="0.0125 -0.1275 0"/>
      <geometry>
        <sphere radius="r3"/>
      </geometry>
      <material name="Red"/>
    </collision>
    <inertial>
      <!-- CENTER OF MASS -->
      <origin rpy="1.57079632679 0 0" xyz="eval[r3/2.] eval[-l3/2.] 0"/>
      <mass value="m3"/>
      <!-- box inertia: 1/12*m(y^2+z^2), ... -->
      <inertia ixx="eval[(m3/12.)*(r3*r3+l3*l3)]" ixy="0" ixz="0" iyy="eval[(m3/12.)*(r3*r3+l3*l3)]" iyz="0" izz="eval[(m3/12.)*(2*r3*r3)]"/>
    </inertial>
  </link>
  <!-- END OF LEG LINKS/JOINTS -->
</robot>

